Workbook

Sheet 使用機器
B2: 機器名 | C2: メーカ名 | D2: 型番 | E2: シリアル
B3: 高電圧試験装置 | C3: パルス電子技術株式会社 | D3: CR-200F-32 | E3: 5477
B4: 試験用変圧器 | C4: 同上 | D4: TT-50K6U | E4: 5477
B5: 直流接地装置 | C5: 同上 | D5: DDC-50K | E5: 5477
B6: 標準球ギャップ | C6: 同上 | D6: G-100H | E6: 5477
B7: 気中／油中試験装置 | C7: 同上 | D7: ZSK-50W | E7: 5477
B8: インパルス電圧発生装置 | C8: 同上 | D8: IVG-200AS | E8: 5477
B9: 懸垂がいし | C9: 同上 | D9: A-S-1527AB JIS記号：180EP
B10: 高電圧プローブ | C10: 同上 | D10: EP-100K
B11: オシロスコープ | C11: Tektronix | D11: TDS 3032 | E11: B012774
B12: デジタルテスタ | C12: マザーツール | D12: MT-8210 | E12: 不明

Sheet 気中火花
B2: 気温 [℃] | E2: 気圧 [hPa] | I2: 相対空気密度 | M2: 相対空気密度（針－針）
B3: 23 | E3: 984 | I3: =0.289*(E3/(273+B3)) -> 0.96072973 | M3: =0.294*(E3/(273+B3)) -> 0.97735135
B6: 平板－平板
B7: ギャップ長 [cm] | F7: 破壊電圧 [kV]
F8: 実験式 | I8: 実測値
I9: 1回目 | L9: 2回目 | O9: 平均値
B10: 0.4 | F10: =23.85*$I$3*(1+(0.329/(SQRT($I$3*B10))))*B10 -> 14.0296 | I10: 13.3 | L10: 13.6 | O10: =AVERAGE(I10:N10) -> 13.45
B11: 0.7 | F11: =23.85*$I$3*(1+(0.329/(SQRT($I$3*B11))))*B11 -> 22.474166 | I11: 22.2 | L11: 20 | O11: =AVERAGE(I11:N11) -> 21.1
B12: 1 | F12: =23.85*$I$3*(1+(0.329/(SQRT($I$3*B12))))*B12 -> 30.604441 | I12: 30.4 | L12: 29.5 | O12: =AVERAGE(I12:N12) -> 29.95
B13: 1.3 | F13: =23.85*$I$3*(1+(0.329/(SQRT($I$3*B13))))*B13 -> 38.556557 | I13: 37.1 | L13: 38.2 | O13: =AVERAGE(I13:N13) -> 37.65
B14: 1.6 | F14: =23.85*$I$3*(1+(0.329/(SQRT($I$3*B14))))*B14 -> 46.389924 | I14: 46.5 | L14: 46.4 | O14: =AVERAGE(I14:N14) -> 46.45
B17: 球－球 | E17: 球半径： | G17: 5 | H17: cm
B18: ギャップ長 [cm] | F18: 破壊電圧 [kV] | S18: 実験式に おける 補正係数
F19: 実験式 | I19: 実測値
I20: 1回目 | L20: 2回目 | O20: 平均値
B21: 0.4 | F21: =27.9*$I$3*(1+(0.533/(SQRT($I$3*$G$17))))*(B21/S21) -> 12.981121 | I21: 14.8 | L21: 13.7 | O21: =AVERAGE(I21:N21) -> 14.25 | S21: =1+(1/3)*(B21/$G$17)+(1/45)*POWER((B21/$G$17),2)+(73/53760)*POWER((B21/$G$17),3) -> 1.0268096
B22: 0.7 | F22: =27.9*$I$3*(1+(0.533/(SQRT($I$3*$G$17))))*(B22/S22) -> 22.276633 | I22: 21.6 | L22: 18.6 | O22: =AVERAGE(I22:N22) -> 20.1 | S22: =1+(1/3)*(B22/$G$17)+(1/45)*POWER((B22/$G$17),2)+(73/53760)*POWER((B22/$G$17),3) -> 1.0471059
B23: 1 | F23: =27.9*$I$3*(1+(0.533/(SQRT($I$3*$G$17))))*(B23/S23) -> 31.213842 | I23: 30.9 | L23: 30.8 | O23: =AVERAGE(I23:N23) -> 30.85 | S23: =1+(1/3)*(B23/$G$17)+(1/45)*POWER((B23/$G$17),2)+(73/53760)*POWER((B23/$G$17),3) -> 1.0675664
B24: 1.3 | F24: =27.9*$I$3*(1+(0.533/(SQRT($I$3*$G$17))))*(B24/S24) -> 39.808852 | I24: 38.2 | L24: 38.8 | O24: =AVERAGE(I24:N24) -> 38.5 | S24: =1+(1/3)*(B24/$G$17)+(1/45)*POWER((B24/$G$17),2)+(73/53760)*POWER((B24/$G$17),3) -> 1.0881928
B25: 1.6 | F25: =27.9*$I$3*(1+(0.533/(SQRT($I$3*$G$17))))*(B25/S25) -> 48.076824 | I25: 44.4 | L25: 46.5 | O25: =AVERAGE(I25:N25) -> 45.45 | S25: =1+(1/3)*(B25/$G$17)+(1/45)*POWER((B25/$G$17),2)+(73/53760)*POWER((B25/$G$17),3) -> 1.1089867
B28: 針－針
B29: ギャップ長 [cm] | F29: 破壊電圧 [kV]
F30: 実験式 | I30: 実測値
I31: 1回目 | L31: 2回目 | O31: 平均値
B32: 1 | F32: =(18.4+5.01*B32)*$M$3 -> 22.879795 | I32: 8.6 | L32: 9.2 | O32: =AVERAGE(I32:N32) -> 8.9
B33: 2 | F33: =(18.4+5.01*B33)*$M$3 -> 27.776325 | I33: 21.5 | L33: 21.5 | O33: =AVERAGE(I33:N33) -> 21.5
B34: 3 | F34: =(18.4+5.01*B34)*$M$3 -> 32.672856 | I34: 31.2 | L34: 31.1 | O34: =AVERAGE(I34:N34) -> 31.15
B35: 4 | F35: =(18.4+5.01*B35)*$M$3 -> 37.569386 | I35: 40.4 | L35: 40.3 | O35: =AVERAGE(I35:N35) -> 40.35
B36: 5 | F36: =(18.4+5.01*B36)*$M$3 -> 42.465916 | I36: 48.3 | L36: 47.8 | O36: =AVERAGE(I36:N36) -> 48.05
B39: 針－平板
B40: ギャップ長 [cm] | F40: 破壊電圧 [kV]
F41: 針（＋） | P41: 針（－）
F42: 1回目 | I42: 2回目 | L42: 平均値 | P42: 1回目 | S42: 2回目 | V42: 平均値
B43: 0.4 | F43: 5.7 | I43: 6.9 | L43: =AVERAGE(F43:K43) -> 6.3 | P43: 7.2 | S43: 7.2 | V43: =AVERAGE(P43:U43) -> 7.2
B44: 0.7 | F44: 7.2 | I44: 6.9 | L44: =AVERAGE(F44:K44) -> 7.05 | P44: 12.6 | S44: 12.5 | V44: =AVERAGE(P44:U44) -> 12.55
B45: 1 | F45: 10.4 | I45: 10.9 | L45: =AVERAGE(F45:K45) -> 10.65 | P45: 18.5 | S45: 18.3 | V45: =AVERAGE(P45:U45) -> 18.4
B46: 1.3 | F46: 14.7 | I46: 15 | L46: =AVERAGE(F46:K46) -> 14.85 | P46: 25 | S46: 25 | V46: =AVERAGE(P46:U46) -> 25
B47: 1.6 | F47: 17.8 | I47: 18.2 | L47: =AVERAGE(F47:K47) -> 18 | P47: 32 | S47: 31.9 | V47: =AVERAGE(P47:U47) -> 31.95

Sheet 液体個体
B2: 絶縁油
B3: 1回目 [kV] | E3: 2回目 [kV] | H3: 3回目 [kV] | K3: 4回目 [kV] | N3: 5回目 [kV] | Q3: 2～5回目の平均値 [kV]
B5: 50.1 | E5: 48.4 | H5: 50.1 | K5: 44.6 | N5: 46.2 | Q5: =AVERAGE(E5,H5,K5,N5) -> 47.325
C7: ギャップ長1cmにおける破壊試験
A8: 実験のギャップ長 | C8: d | D8: 0.25
C9: n | D9: 0.5
C10: A | D10: =Q5/(POWER(D8,D9)) -> 94.65
A11: ギャップ長1cmの破壊電圧 | C11: V | D11: =D10*(POWER(1,D9)) -> 94.65
B14: ベークライト
B15: 1回目 [kV] | E15: 2回目 [kV] | H15: 平均値 [kV] | K15: 波高値（√2×平均値） [kV]
B17: 42.4 | E17: 44.2 | H17: =AVERAGE(B17,E17) -> 43.3 | K17: =SQRT(2)*H17 -> 61.235447
C19: ギャップ長1cmにおける破壊試験
A20: 実験のギャップ長 | C20: d | D20: 0.1
C21: n | D21: 0.6
C22: A | D22: =K17/(POWER(D20,D21)) -> 243.78271
A23: ギャップ長1cmの破壊電圧 | C23: V | D23: =D22*(POWER(1,D21)) -> 243.78271
B26: 気体、液体、固体の 破壊電圧の比較
G27: 気体 （空気） | K27: 液体 （絶縁油） | O27: 固体 （ベークライト）
B29: 破壊電圧 | G29: =気中火花!O12 -> 29.95 | K29: =D11 -> 94.65 | O29: =D23 -> 243.78271
B30: 気体に対する比 | G30: =G29/$G$29 -> 1 | K30: =K29/$G$29 -> 3.1602671 | O30: =O29/$G$29 -> 8.1396563

Sheet 碍子インパルス
B2: 充電電圧 Vi [kV] | C2: インパルス電圧 Vo [kV] | D2: フラッシオーバの有無（有 : 〇，無 : ×） | Z2: 放電率 p [%]
D3: 1 | F3: 2 | H3: 3 | J3: 4 | L3: 5 | N3: 6 | P3: 7 | R3: 8 | T3: 9 | V3: 10 | X3: 回目
B4: 27.2 | C4: =B4*4*0.846 -> 92.0448 | D4: × | F4: × | H4: × | J4: 〇 | L4: × | N4: 〇 | P4: × | R4: × | T4: × | V4: 〇 | Z4: =((COUNTIF(D4:W4,"〇"))/(COUNTA(D4:W4)))*100 -> 30
B5: 27.6 | C5: =B5*4*0.846 -> 93.3984 | D5: 〇 | F5: 〇 | H5: × | J5: 〇 | L5: 〇 | N5: 〇 | P5: × | R5: 〇 | T5: 〇 | V5: 〇 | Z5: =((COUNTIF(D5:W5,"〇"))/(COUNTA(D5:W5)))*100 -> 80
D6: 傾き: | G6: =(Z5-Z4)/(C5-C4) -> 36.938534
D7: 切片: | G7: =Z5-((Z5-Z4)/(C5-C4))*C5 -> -3370
D8: 50 | F8: %フラッシオーバ電圧： | P8: =(D8-$G7)/$G6 -> 92.58624 | S8: kV
D9: 碍子の対雷インパルス電圧に対する比： | W9: =P8/75 -> 1.2344832
D10: 自分の抵抗値： | L10: 374 | P10: kΩ
D11: 50%フラッシオーバ電圧の感電時に流れる電流： | Z11: =P8/L10*1000 -> 247.55679 | AC11: mA
D12: 0 | F12: %フラッシオーバ電圧： | P12: =(D12-$G7)/$G6 -> 91.23264
D13: 標準状態におけるフラッシオーバが0%となる電圧： | AB13: =P12/気中火花!$I$3 -> 94.961816
D14: 碍子の対雷インパルス電圧に対する比： | W14: =AB13/75 -> 1.2661575
B16: 充電電圧 Vi [kV] | C16: インパルス電圧 Vo [kV] | D16: フラッシオーバの有無（有 : 〇，無 : ×） | Z16: 放電率 p [%]
D17: 1 | F17: 2 | H17: 3 | J17: 4 | L17: 5 | N17: 6 | P17: 7 | R17: 8 | T17: 9 | V17: 10 | X17: 回目
B18: 27 | C18: =B18*4*0.846 -> 91.368 | D18: × | F18: × | H18: × | J18: × | L18: × | N18: × | P18: 〇 | R18: × | T18: × | V18: × | Z18: =((COUNTIF(D18:W18,"〇"))/(COUNTA(D18:W18)))*100 -> 10
B19: 27.2 | C19: =B19*4*0.846 -> 92.0448 | D19: × | F19: × | H19: × | J19: 〇 | L19: × | N19: 〇 | P19: × | R19: × | T19: × | V19: 〇 | Z19: =((COUNTIF(D19:W19,"〇"))/(COUNTA(D19:W19)))*100 -> 30
B20: 27.6 | C20: =B20*4*0.846 -> 93.3984 | D20: 〇 | F20: 〇 | H20: × | J20: 〇 | L20: 〇 | N20: 〇 | P20: × | R20: 〇 | T20: 〇 | V20: 〇 | Z20: =((COUNTIF(D20:W20,"〇"))/(COUNTA(D20:W20)))*100 -> 80
D21: 傾き: | G21: =(Z20-Z19)/(C20-C19) -> 36.938534
D22: 切片: | G22: =Z20-((Z20-Z19)/(C20-C19))*C20 -> -3370
D23: 50 | F23: %フラッシオーバ電圧： | P23: =(D23-$G22)/$G21 -> 92.58624 | S23: kV
D24: 碍子の対雷インパルス電圧に対する比： | W24: =P23/75 -> 1.2344832
D25: 自分の抵抗値： | L25: 374 | P25: kΩ
D26: 50%フラッシオーバ電圧の感電時に流れる電流： | Z26: =P23/L25*1000 -> 247.55679 | AC26: mA
D27: 0 | F27: %フラッシオーバ電圧： | P27: =(D27-$G22)/$G21 -> 91.23264
D28: 標準状態におけるフラッシオーバが0%となる電圧： | AB28: =P27/気中火花!$I$3 -> 94.961816
D29: 碍子の対雷インパルス電圧に対する比： | W29: =AB28/75 -> 1.2661575
B31: 充電電圧 Vi [kV] | C31: インパルス電圧 Vo [kV] | D31: フラッシのオーバ有無（有 : 〇，無 : ×） | AB31: 放電率 p [%]
D32: 1 | F32: 2 | H32: 3 | J32: 4 | L32: 5 | N32: 6 | P32: 7 | R32: 8 | T32: 9 | V32: 10 | X32: 11 | Z32: 回目
B33: 27.2 | C33: =B33*4*0.846 -> 92.0448 | D33: × | F33: × | H33: × | J33: × | L33: 〇 | N33: × | P33: × | R33: × | T33: × | V33: × | X33: × | AB33: =((COUNTIF(D33:Y33,"〇"))/(COUNTA(D33:Y33)))*100 -> 9.0909091
B34: 27.4 | C34: =B34*4*0.846 -> 92.7216 | D34: × | F34: 〇 | H34: × | J34: 〇 | L34: × | N34: 〇 | P34: × | R34: 〇 | T34: × | V34: 〇 | X34: × | AB34: =((COUNTIF(D34:Y34,"〇"))/(COUNTA(D34:Y34)))*100 -> 45.454545
B35: 27.8 | C35: =B35*4*0.846 -> 94.0752 | D35: 〇 | F35: 〇 | H35: × | J35: 〇 | L35: 〇 | N35: 〇 | P35: × | R35: 〇 | T35: 〇 | V35: 〇 | AB35: =((COUNTIF(D35:Y35,"〇"))/(COUNTA(D35:Y35)))*100 -> 80
D36: 傾き: | G36: =(AB35-AB34)/(C35-C34) -> 25.521169
D37: 切片: | G37: =AB35-((AB35-AB34)/(C35-C34))*C35 -> -2320.9091
D38: 50 | F38: %フラッシオーバ電圧： | P38: =(D38-$G37)/$G36 -> 92.899705 | S38: kV
D39: 碍子の対雷インパルス電圧に対する比： | W39: =P38/75 -> 1.2386627
D40: 自分の抵抗値： | L40: 374 | P40: kΩ
D41: 50%フラッシオーバ電圧の感電時に流れる電流： | Z41: =P38/L40*1000 -> 248.39493 | AC41: mA
D42: 0 | F42: %フラッシオーバ電圧： | P42: =(D42-$G37)/$G36 -> 90.940547
D43: 標準状態におけるフラッシオーバが0%となる電圧： | AB43: =P42/気中火花!$I$3 -> 94.657784
...
